{"uid":"70a30d8221a9073a","name":"test_basic_setup[chrome]","fullName":"tests.basic_test.TestBasic#test_basic_setup","historyId":"d8e196c5bf0e40e1f6371b2b68db7725","time":{"start":1740707070900,"stop":1740707070900,"duration":0},"description":"Basic test to verify setup is working","descriptionHtml":"<p>Basic test to verify setup is working</p>\n","status":"failed","statusMessage":"Failed: Could not initialize WebDriver for chrome: Message: unknown error: net::ERR_CONNECTION_REFUSED\n  (Session info: chrome=128.0.6613.137)\nStacktrace:\n#0 0x562b7b6a30ca <unknown>\n#1 0x562b7b36f2b0 <unknown>\n#2 0x562b7b367471 <unknown>\n#3 0x562b7b357649 <unknown>\n#4 0x562b7b3593b4 <unknown>\n#5 0x562b7b3578fd <unknown>\n#6 0x562b7b35717c <unknown>\n#7 0x562b7b35706d <unknown>\n#8 0x562b7b355078 <unknown>\n#9 0x562b7b35570a <unknown>\n#10 0x562b7b371bd1 <unknown>\n#11 0x562b7b402975 <unknown>\n#12 0x562b7b3e3902 <unknown>\n#13 0x562b7b401e26 <unknown>\n#14 0x562b7b3e36a3 <unknown>\n#15 0x562b7b3b14f3 <unknown>\n#16 0x562b7b3b24fe <unknown>\n#17 0x562b7b669d7b <unknown>\n#18 0x562b7b66dd31 <unknown>\n#19 0x562b7b655c85 <unknown>\n#20 0x562b7b66e8a2 <unknown>\n#21 0x562b7b63ae1f <unknown>\n#22 0x562b7b691e48 <unknown>\n#23 0x562b7b692013 <unknown>\n#24 0x562b7b6a1ebc <unknown>\n#25 0x7fe955c33ac3 <unknown>","statusTrace":"Traceback (most recent call last):\n  File \"/app/conftest.py\", line 88, in driver\n    driver.get(base_url)\n  File \"/usr/local/lib/python3.10/site-packages/selenium/webdriver/remote/webdriver.py\", line 356, in get\n    self.execute(Command.GET, {\"url\": url})\n  File \"/usr/local/lib/python3.10/site-packages/selenium/webdriver/remote/webdriver.py\", line 347, in execute\n    self.error_handler.check_response(response)\n  File \"/usr/local/lib/python3.10/site-packages/selenium/webdriver/remote/errorhandler.py\", line 229, in check_response\n    raise exception_class(message, screen, stacktrace)\nselenium.common.exceptions.WebDriverException: Message: unknown error: net::ERR_CONNECTION_REFUSED\n  (Session info: chrome=128.0.6613.137)\nStacktrace:\n#0 0x562b7b6a30ca <unknown>\n#1 0x562b7b36f2b0 <unknown>\n#2 0x562b7b367471 <unknown>\n#3 0x562b7b357649 <unknown>\n#4 0x562b7b3593b4 <unknown>\n#5 0x562b7b3578fd <unknown>\n#6 0x562b7b35717c <unknown>\n#7 0x562b7b35706d <unknown>\n#8 0x562b7b355078 <unknown>\n#9 0x562b7b35570a <unknown>\n#10 0x562b7b371bd1 <unknown>\n#11 0x562b7b402975 <unknown>\n#12 0x562b7b3e3902 <unknown>\n#13 0x562b7b401e26 <unknown>\n#14 0x562b7b3e36a3 <unknown>\n#15 0x562b7b3b14f3 <unknown>\n#16 0x562b7b3b24fe <unknown>\n#17 0x562b7b669d7b <unknown>\n#18 0x562b7b66dd31 <unknown>\n#19 0x562b7b655c85 <unknown>\n#20 0x562b7b66e8a2 <unknown>\n#21 0x562b7b63ae1f <unknown>\n#22 0x562b7b691e48 <unknown>\n#23 0x562b7b692013 <unknown>\n#24 0x562b7b6a1ebc <unknown>\n#25 0x7fe955c33ac3 <unknown>\n\n\nDuring handling of the above exception, another exception occurred:\n\nTraceback (most recent call last):\n  File \"/usr/local/lib/python3.10/site-packages/_pytest/runner.py\", line 341, in from_call\n    result: Optional[TResult] = func()\n  File \"/usr/local/lib/python3.10/site-packages/_pytest/runner.py\", line 262, in <lambda>\n    lambda: ihook(item=item, **kwds), when=when, reraise=reraise\n  File \"/usr/local/lib/python3.10/site-packages/pluggy/_hooks.py\", line 513, in __call__\n    return self._hookexec(self.name, self._hookimpls.copy(), kwargs, firstresult)\n  File \"/usr/local/lib/python3.10/site-packages/pluggy/_manager.py\", line 120, in _hookexec\n    return self._inner_hookexec(hook_name, methods, kwargs, firstresult)\n  File \"/usr/local/lib/python3.10/site-packages/pluggy/_callers.py\", line 182, in _multicall\n    return outcome.get_result()\n  File \"/usr/local/lib/python3.10/site-packages/pluggy/_result.py\", line 100, in get_result\n    raise exc.with_traceback(exc.__traceback__)\n  File \"/usr/local/lib/python3.10/site-packages/pluggy/_callers.py\", line 103, in _multicall\n    res = hook_impl.function(*args)\n  File \"/usr/local/lib/python3.10/site-packages/_pytest/runner.py\", line 157, in pytest_runtest_setup\n    item.session._setupstate.setup(item)\n  File \"/usr/local/lib/python3.10/site-packages/_pytest/runner.py\", line 497, in setup\n    raise exc\n  File \"/usr/local/lib/python3.10/site-packages/_pytest/runner.py\", line 494, in setup\n    col.setup()\n  File \"/usr/local/lib/python3.10/site-packages/_pytest/python.py\", line 1795, in setup\n    self._request._fillfixtures()\n  File \"/usr/local/lib/python3.10/site-packages/_pytest/fixtures.py\", line 566, in _fillfixtures\n    item.funcargs[argname] = self.getfixturevalue(argname)\n  File \"/usr/local/lib/python3.10/site-packages/_pytest/fixtures.py\", line 585, in getfixturevalue\n    fixturedef = self._get_active_fixturedef(argname)\n  File \"/usr/local/lib/python3.10/site-packages/_pytest/fixtures.py\", line 607, in _get_active_fixturedef\n    self._compute_fixture_value(fixturedef)\n  File \"/usr/local/lib/python3.10/site-packages/_pytest/fixtures.py\", line 693, in _compute_fixture_value\n    fixturedef.execute(request=subrequest)\n  File \"/usr/local/lib/python3.10/site-packages/_pytest/fixtures.py\", line 1069, in execute\n    result = ihook.pytest_fixture_setup(fixturedef=self, request=request)\n  File \"/usr/local/lib/python3.10/site-packages/pluggy/_hooks.py\", line 513, in __call__\n    return self._hookexec(self.name, self._hookimpls.copy(), kwargs, firstresult)\n  File \"/usr/local/lib/python3.10/site-packages/pluggy/_manager.py\", line 120, in _hookexec\n    return self._inner_hookexec(hook_name, methods, kwargs, firstresult)\n  File \"/usr/local/lib/python3.10/site-packages/pluggy/_callers.py\", line 182, in _multicall\n    return outcome.get_result()\n  File \"/usr/local/lib/python3.10/site-packages/pluggy/_result.py\", line 100, in get_result\n    raise exc.with_traceback(exc.__traceback__)\n  File \"/usr/local/lib/python3.10/site-packages/pluggy/_callers.py\", line 103, in _multicall\n    res = hook_impl.function(*args)\n  File \"/usr/local/lib/python3.10/site-packages/_pytest/fixtures.py\", line 1123, in pytest_fixture_setup\n    result = call_fixture_func(fixturefunc, request, kwargs)\n  File \"/usr/local/lib/python3.10/site-packages/_pytest/fixtures.py\", line 895, in call_fixture_func\n    fixture_result = next(generator)\n  File \"/app/conftest.py\", line 96, in driver\n    pytest.fail(f\"Could not initialize WebDriver for {selenium_browser}: {str(e)}\")\n  File \"/usr/local/lib/python3.10/site-packages/_pytest/outcomes.py\", line 198, in fail\n    raise Failed(msg=reason, pytrace=pytrace)\nFailed: Could not initialize WebDriver for chrome: Message: unknown error: net::ERR_CONNECTION_REFUSED\n  (Session info: chrome=128.0.6613.137)\nStacktrace:\n#0 0x562b7b6a30ca <unknown>\n#1 0x562b7b36f2b0 <unknown>\n#2 0x562b7b367471 <unknown>\n#3 0x562b7b357649 <unknown>\n#4 0x562b7b3593b4 <unknown>\n#5 0x562b7b3578fd <unknown>\n#6 0x562b7b35717c <unknown>\n#7 0x562b7b35706d <unknown>\n#8 0x562b7b355078 <unknown>\n#9 0x562b7b35570a <unknown>\n#10 0x562b7b371bd1 <unknown>\n#11 0x562b7b402975 <unknown>\n#12 0x562b7b3e3902 <unknown>\n#13 0x562b7b401e26 <unknown>\n#14 0x562b7b3e36a3 <unknown>\n#15 0x562b7b3b14f3 <unknown>\n#16 0x562b7b3b24fe <unknown>\n#17 0x562b7b669d7b <unknown>\n#18 0x562b7b66dd31 <unknown>\n#19 0x562b7b655c85 <unknown>\n#20 0x562b7b66e8a2 <unknown>\n#21 0x562b7b63ae1f <unknown>\n#22 0x562b7b691e48 <unknown>\n#23 0x562b7b692013 <unknown>\n#24 0x562b7b6a1ebc <unknown>\n#25 0x7fe955c33ac3 <unknown>","flaky":false,"newFailed":false,"newBroken":false,"newPassed":false,"retriesCount":0,"retriesStatusChange":false,"beforeStages":[{"name":"base_url","time":{"start":1740707070900,"stop":1740707070901,"duration":1},"status":"passed","steps":[],"attachments":[],"parameters":[],"stepsCount":0,"attachmentsCount":0,"shouldDisplayMessage":false,"hasContent":false,"attachmentStep":false},{"name":"pytestconfig","time":{"start":1740707070901,"stop":1740707070901,"duration":0},"status":"passed","steps":[],"attachments":[],"parameters":[],"stepsCount":0,"attachmentsCount":0,"shouldDisplayMessage":false,"hasContent":false,"attachmentStep":false},{"name":"delete_output_dir","time":{"start":1740707070901,"stop":1740707070901,"duration":0},"status":"passed","steps":[],"attachments":[],"parameters":[],"stepsCount":0,"attachmentsCount":0,"shouldDisplayMessage":false,"hasContent":false,"attachmentStep":false},{"name":"_session_faker","time":{"start":1740707070901,"stop":1740707070969,"duration":68},"status":"passed","steps":[],"attachments":[],"parameters":[],"stepsCount":0,"attachmentsCount":0,"shouldDisplayMessage":false,"hasContent":false,"attachmentStep":false},{"name":"_verify_url","time":{"start":1740707070901,"stop":1740707070901,"duration":0},"status":"passed","steps":[],"attachments":[],"parameters":[],"stepsCount":0,"attachmentsCount":0,"shouldDisplayMessage":false,"hasContent":false,"attachmentStep":false},{"name":"sensitive_url","time":{"start":1740707070969,"stop":1740707070970,"duration":1},"status":"passed","steps":[],"attachments":[],"parameters":[],"stepsCount":0,"attachmentsCount":0,"shouldDisplayMessage":false,"hasContent":false,"attachmentStep":false},{"name":"remote_url","time":{"start":1740707070970,"stop":1740707070970,"duration":0},"status":"passed","steps":[],"attachments":[],"parameters":[],"stepsCount":0,"attachmentsCount":0,"shouldDisplayMessage":false,"hasContent":false,"attachmentStep":false},{"name":"driver","time":{"start":1740707070970,"stop":1740707097198,"duration":26228},"status":"failed","statusMessage":"Failed: Could not initialize WebDriver for chrome: Message: unknown error: net::ERR_CONNECTION_REFUSED\n  (Session info: chrome=128.0.6613.137)\nStacktrace:\n#0 0x562b7b6a30ca <unknown>\n#1 0x562b7b36f2b0 <unknown>\n#2 0x562b7b367471 <unknown>\n#3 0x562b7b357649 <unknown>\n#4 0x562b7b3593b4 <unknown>\n#5 0x562b7b3578fd <unknown>\n#6 0x562b7b35717c <unknown>\n#7 0x562b7b35706d <unknown>\n#8 0x562b7b355078 <unknown>\n#9 0x562b7b35570a <unknown>\n#10 0x562b7b371bd1 <unknown>\n#11 0x562b7b402975 <unknown>\n#12 0x562b7b3e3902 <unknown>\n#13 0x562b7b401e26 <unknown>\n#14 0x562b7b3e36a3 <unknown>\n#15 0x562b7b3b14f3 <unknown>\n#16 0x562b7b3b24fe <unknown>\n#17 0x562b7b669d7b <unknown>\n#18 0x562b7b66dd31 <unknown>\n#19 0x562b7b655c85 <unknown>\n#20 0x562b7b66e8a2 <unknown>\n#21 0x562b7b63ae1f <unknown>\n#22 0x562b7b691e48 <unknown>\n#23 0x562b7b692013 <unknown>\n#24 0x562b7b6a1ebc <unknown>\n#25 0x7fe955c33ac3 <unknown>\n\n","statusTrace":"  File \"/usr/local/lib/python3.10/site-packages/pluggy/_callers.py\", line 103, in _multicall\n    res = hook_impl.function(*args)\n  File \"/usr/local/lib/python3.10/site-packages/_pytest/fixtures.py\", line 1123, in pytest_fixture_setup\n    result = call_fixture_func(fixturefunc, request, kwargs)\n  File \"/usr/local/lib/python3.10/site-packages/_pytest/fixtures.py\", line 895, in call_fixture_func\n    fixture_result = next(generator)\n  File \"/app/conftest.py\", line 96, in driver\n    pytest.fail(f\"Could not initialize WebDriver for {selenium_browser}: {str(e)}\")\n  File \"/usr/local/lib/python3.10/site-packages/_pytest/outcomes.py\", line 198, in fail\n    raise Failed(msg=reason, pytrace=pytrace)\n","steps":[],"attachments":[{"uid":"cbd75350ac7b3d25","name":"webdriver_exception_chrome","source":"cbd75350ac7b3d25.txt","type":"text/plain","size":848}],"parameters":[],"stepsCount":0,"attachmentsCount":1,"shouldDisplayMessage":true,"hasContent":true,"attachmentStep":false},{"name":"_skip_sensitive","time":{"start":1740707070970,"stop":1740707070970,"duration":0},"status":"passed","steps":[],"attachments":[],"parameters":[],"stepsCount":0,"attachmentsCount":0,"shouldDisplayMessage":false,"hasContent":false,"attachmentStep":false}],"testStage":{"description":"Basic test to verify setup is working","status":"failed","statusMessage":"Failed: Could not initialize WebDriver for chrome: Message: unknown error: net::ERR_CONNECTION_REFUSED\n  (Session info: chrome=128.0.6613.137)\nStacktrace:\n#0 0x562b7b6a30ca <unknown>\n#1 0x562b7b36f2b0 <unknown>\n#2 0x562b7b367471 <unknown>\n#3 0x562b7b357649 <unknown>\n#4 0x562b7b3593b4 <unknown>\n#5 0x562b7b3578fd <unknown>\n#6 0x562b7b35717c <unknown>\n#7 0x562b7b35706d <unknown>\n#8 0x562b7b355078 <unknown>\n#9 0x562b7b35570a <unknown>\n#10 0x562b7b371bd1 <unknown>\n#11 0x562b7b402975 <unknown>\n#12 0x562b7b3e3902 <unknown>\n#13 0x562b7b401e26 <unknown>\n#14 0x562b7b3e36a3 <unknown>\n#15 0x562b7b3b14f3 <unknown>\n#16 0x562b7b3b24fe <unknown>\n#17 0x562b7b669d7b <unknown>\n#18 0x562b7b66dd31 <unknown>\n#19 0x562b7b655c85 <unknown>\n#20 0x562b7b66e8a2 <unknown>\n#21 0x562b7b63ae1f <unknown>\n#22 0x562b7b691e48 <unknown>\n#23 0x562b7b692013 <unknown>\n#24 0x562b7b6a1ebc <unknown>\n#25 0x7fe955c33ac3 <unknown>","statusTrace":"Traceback (most recent call last):\n  File \"/app/conftest.py\", line 88, in driver\n    driver.get(base_url)\n  File \"/usr/local/lib/python3.10/site-packages/selenium/webdriver/remote/webdriver.py\", line 356, in get\n    self.execute(Command.GET, {\"url\": url})\n  File \"/usr/local/lib/python3.10/site-packages/selenium/webdriver/remote/webdriver.py\", line 347, in execute\n    self.error_handler.check_response(response)\n  File \"/usr/local/lib/python3.10/site-packages/selenium/webdriver/remote/errorhandler.py\", line 229, in check_response\n    raise exception_class(message, screen, stacktrace)\nselenium.common.exceptions.WebDriverException: Message: unknown error: net::ERR_CONNECTION_REFUSED\n  (Session info: chrome=128.0.6613.137)\nStacktrace:\n#0 0x562b7b6a30ca <unknown>\n#1 0x562b7b36f2b0 <unknown>\n#2 0x562b7b367471 <unknown>\n#3 0x562b7b357649 <unknown>\n#4 0x562b7b3593b4 <unknown>\n#5 0x562b7b3578fd <unknown>\n#6 0x562b7b35717c <unknown>\n#7 0x562b7b35706d <unknown>\n#8 0x562b7b355078 <unknown>\n#9 0x562b7b35570a <unknown>\n#10 0x562b7b371bd1 <unknown>\n#11 0x562b7b402975 <unknown>\n#12 0x562b7b3e3902 <unknown>\n#13 0x562b7b401e26 <unknown>\n#14 0x562b7b3e36a3 <unknown>\n#15 0x562b7b3b14f3 <unknown>\n#16 0x562b7b3b24fe <unknown>\n#17 0x562b7b669d7b <unknown>\n#18 0x562b7b66dd31 <unknown>\n#19 0x562b7b655c85 <unknown>\n#20 0x562b7b66e8a2 <unknown>\n#21 0x562b7b63ae1f <unknown>\n#22 0x562b7b691e48 <unknown>\n#23 0x562b7b692013 <unknown>\n#24 0x562b7b6a1ebc <unknown>\n#25 0x7fe955c33ac3 <unknown>\n\n\nDuring handling of the above exception, another exception occurred:\n\nTraceback (most recent call last):\n  File \"/usr/local/lib/python3.10/site-packages/_pytest/runner.py\", line 341, in from_call\n    result: Optional[TResult] = func()\n  File \"/usr/local/lib/python3.10/site-packages/_pytest/runner.py\", line 262, in <lambda>\n    lambda: ihook(item=item, **kwds), when=when, reraise=reraise\n  File \"/usr/local/lib/python3.10/site-packages/pluggy/_hooks.py\", line 513, in __call__\n    return self._hookexec(self.name, self._hookimpls.copy(), kwargs, firstresult)\n  File \"/usr/local/lib/python3.10/site-packages/pluggy/_manager.py\", line 120, in _hookexec\n    return self._inner_hookexec(hook_name, methods, kwargs, firstresult)\n  File \"/usr/local/lib/python3.10/site-packages/pluggy/_callers.py\", line 182, in _multicall\n    return outcome.get_result()\n  File \"/usr/local/lib/python3.10/site-packages/pluggy/_result.py\", line 100, in get_result\n    raise exc.with_traceback(exc.__traceback__)\n  File \"/usr/local/lib/python3.10/site-packages/pluggy/_callers.py\", line 103, in _multicall\n    res = hook_impl.function(*args)\n  File \"/usr/local/lib/python3.10/site-packages/_pytest/runner.py\", line 157, in pytest_runtest_setup\n    item.session._setupstate.setup(item)\n  File \"/usr/local/lib/python3.10/site-packages/_pytest/runner.py\", line 497, in setup\n    raise exc\n  File \"/usr/local/lib/python3.10/site-packages/_pytest/runner.py\", line 494, in setup\n    col.setup()\n  File \"/usr/local/lib/python3.10/site-packages/_pytest/python.py\", line 1795, in setup\n    self._request._fillfixtures()\n  File \"/usr/local/lib/python3.10/site-packages/_pytest/fixtures.py\", line 566, in _fillfixtures\n    item.funcargs[argname] = self.getfixturevalue(argname)\n  File \"/usr/local/lib/python3.10/site-packages/_pytest/fixtures.py\", line 585, in getfixturevalue\n    fixturedef = self._get_active_fixturedef(argname)\n  File \"/usr/local/lib/python3.10/site-packages/_pytest/fixtures.py\", line 607, in _get_active_fixturedef\n    self._compute_fixture_value(fixturedef)\n  File \"/usr/local/lib/python3.10/site-packages/_pytest/fixtures.py\", line 693, in _compute_fixture_value\n    fixturedef.execute(request=subrequest)\n  File \"/usr/local/lib/python3.10/site-packages/_pytest/fixtures.py\", line 1069, in execute\n    result = ihook.pytest_fixture_setup(fixturedef=self, request=request)\n  File \"/usr/local/lib/python3.10/site-packages/pluggy/_hooks.py\", line 513, in __call__\n    return self._hookexec(self.name, self._hookimpls.copy(), kwargs, firstresult)\n  File \"/usr/local/lib/python3.10/site-packages/pluggy/_manager.py\", line 120, in _hookexec\n    return self._inner_hookexec(hook_name, methods, kwargs, firstresult)\n  File \"/usr/local/lib/python3.10/site-packages/pluggy/_callers.py\", line 182, in _multicall\n    return outcome.get_result()\n  File \"/usr/local/lib/python3.10/site-packages/pluggy/_result.py\", line 100, in get_result\n    raise exc.with_traceback(exc.__traceback__)\n  File \"/usr/local/lib/python3.10/site-packages/pluggy/_callers.py\", line 103, in _multicall\n    res = hook_impl.function(*args)\n  File \"/usr/local/lib/python3.10/site-packages/_pytest/fixtures.py\", line 1123, in pytest_fixture_setup\n    result = call_fixture_func(fixturefunc, request, kwargs)\n  File \"/usr/local/lib/python3.10/site-packages/_pytest/fixtures.py\", line 895, in call_fixture_func\n    fixture_result = next(generator)\n  File \"/app/conftest.py\", line 96, in driver\n    pytest.fail(f\"Could not initialize WebDriver for {selenium_browser}: {str(e)}\")\n  File \"/usr/local/lib/python3.10/site-packages/_pytest/outcomes.py\", line 198, in fail\n    raise Failed(msg=reason, pytrace=pytrace)\nFailed: Could not initialize WebDriver for chrome: Message: unknown error: net::ERR_CONNECTION_REFUSED\n  (Session info: chrome=128.0.6613.137)\nStacktrace:\n#0 0x562b7b6a30ca <unknown>\n#1 0x562b7b36f2b0 <unknown>\n#2 0x562b7b367471 <unknown>\n#3 0x562b7b357649 <unknown>\n#4 0x562b7b3593b4 <unknown>\n#5 0x562b7b3578fd <unknown>\n#6 0x562b7b35717c <unknown>\n#7 0x562b7b35706d <unknown>\n#8 0x562b7b355078 <unknown>\n#9 0x562b7b35570a <unknown>\n#10 0x562b7b371bd1 <unknown>\n#11 0x562b7b402975 <unknown>\n#12 0x562b7b3e3902 <unknown>\n#13 0x562b7b401e26 <unknown>\n#14 0x562b7b3e36a3 <unknown>\n#15 0x562b7b3b14f3 <unknown>\n#16 0x562b7b3b24fe <unknown>\n#17 0x562b7b669d7b <unknown>\n#18 0x562b7b66dd31 <unknown>\n#19 0x562b7b655c85 <unknown>\n#20 0x562b7b66e8a2 <unknown>\n#21 0x562b7b63ae1f <unknown>\n#22 0x562b7b691e48 <unknown>\n#23 0x562b7b692013 <unknown>\n#24 0x562b7b6a1ebc <unknown>\n#25 0x7fe955c33ac3 <unknown>","steps":[],"attachments":[{"uid":"703be67315eaa588","name":"log","source":"703be67315eaa588.txt","type":"text/plain","size":730},{"uid":"1b107ba69e3b4ecc","name":"stdout","source":"1b107ba69e3b4ecc.txt","type":"text/plain","size":738}],"parameters":[],"stepsCount":0,"attachmentsCount":2,"shouldDisplayMessage":true,"hasContent":true,"attachmentStep":false},"afterStages":[],"labels":[{"name":"epic","value":"Setup Verification"},{"name":"severity","value":"normal"},{"name":"story","value":"Simple Test"},{"name":"feature","value":"Basic Test"},{"name":"tag","value":"nondestructive"},{"name":"parentSuite","value":"tests"},{"name":"suite","value":"basic_test"},{"name":"subSuite","value":"TestBasic"},{"name":"host","value":"bc5af2ad4740"},{"name":"thread","value":"1-MainThread"},{"name":"framework","value":"pytest"},{"name":"language","value":"cpython3"},{"name":"package","value":"tests.basic_test"},{"name":"resultFormat","value":"allure2"}],"parameters":[{"name":"selenium_browser","value":"'chrome'"}],"links":[],"hidden":true,"retry":true,"extra":{"categories":[],"tags":["nondestructive"]},"source":"70a30d8221a9073a.json","parameterValues":["'chrome'"]}