{"uid":"b61f3aef7729b469","name":"test_basic_setup[chrome]","fullName":"tests.basic_test.TestBasic#test_basic_setup","historyId":"d8e196c5bf0e40e1f6371b2b68db7725","time":{"start":1740704058753,"stop":1740704058753,"duration":0},"description":"Basic test to verify setup is working","descriptionHtml":"<p>Basic test to verify setup is working</p>\n","status":"failed","statusMessage":"Failed: Could not initialize WebDriver for chrome: Message: wait: http://172.17.0.4:4444/ does not respond in 30s","statusTrace":"Traceback (most recent call last):\n  File \"/app/conftest.py\", line 73, in driver\n    driver = WebDriverFactory.create_driver(\n  File \"/app/utils/webdriver_factory.py\", line 167, in create_driver\n    driver = WebDriverFactory._create_chrome_driver(\n  File \"/app/utils/webdriver_factory.py\", line 315, in _create_chrome_driver\n    driver = webdriver.Remote(\n  File \"/usr/local/lib/python3.10/site-packages/selenium/webdriver/remote/webdriver.py\", line 208, in __init__\n    self.start_session(capabilities)\n  File \"/usr/local/lib/python3.10/site-packages/selenium/webdriver/remote/webdriver.py\", line 292, in start_session\n    response = self.execute(Command.NEW_SESSION, caps)[\"value\"]\n  File \"/usr/local/lib/python3.10/site-packages/selenium/webdriver/remote/webdriver.py\", line 347, in execute\n    self.error_handler.check_response(response)\n  File \"/usr/local/lib/python3.10/site-packages/selenium/webdriver/remote/errorhandler.py\", line 229, in check_response\n    raise exception_class(message, screen, stacktrace)\nselenium.common.exceptions.SessionNotCreatedException: Message: wait: http://172.17.0.4:4444/ does not respond in 30s\n\n\nDuring handling of the above exception, another exception occurred:\n\nTraceback (most recent call last):\n  File \"/usr/local/lib/python3.10/site-packages/_pytest/runner.py\", line 341, in from_call\n    result: Optional[TResult] = func()\n  File \"/usr/local/lib/python3.10/site-packages/_pytest/runner.py\", line 262, in <lambda>\n    lambda: ihook(item=item, **kwds), when=when, reraise=reraise\n  File \"/usr/local/lib/python3.10/site-packages/pluggy/_hooks.py\", line 513, in __call__\n    return self._hookexec(self.name, self._hookimpls.copy(), kwargs, firstresult)\n  File \"/usr/local/lib/python3.10/site-packages/pluggy/_manager.py\", line 120, in _hookexec\n    return self._inner_hookexec(hook_name, methods, kwargs, firstresult)\n  File \"/usr/local/lib/python3.10/site-packages/pluggy/_callers.py\", line 182, in _multicall\n    return outcome.get_result()\n  File \"/usr/local/lib/python3.10/site-packages/pluggy/_result.py\", line 100, in get_result\n    raise exc.with_traceback(exc.__traceback__)\n  File \"/usr/local/lib/python3.10/site-packages/pluggy/_callers.py\", line 103, in _multicall\n    res = hook_impl.function(*args)\n  File \"/usr/local/lib/python3.10/site-packages/_pytest/runner.py\", line 157, in pytest_runtest_setup\n    item.session._setupstate.setup(item)\n  File \"/usr/local/lib/python3.10/site-packages/_pytest/runner.py\", line 497, in setup\n    raise exc\n  File \"/usr/local/lib/python3.10/site-packages/_pytest/runner.py\", line 494, in setup\n    col.setup()\n  File \"/usr/local/lib/python3.10/site-packages/_pytest/python.py\", line 1795, in setup\n    self._request._fillfixtures()\n  File \"/usr/local/lib/python3.10/site-packages/_pytest/fixtures.py\", line 566, in _fillfixtures\n    item.funcargs[argname] = self.getfixturevalue(argname)\n  File \"/usr/local/lib/python3.10/site-packages/_pytest/fixtures.py\", line 585, in getfixturevalue\n    fixturedef = self._get_active_fixturedef(argname)\n  File \"/usr/local/lib/python3.10/site-packages/_pytest/fixtures.py\", line 607, in _get_active_fixturedef\n    self._compute_fixture_value(fixturedef)\n  File \"/usr/local/lib/python3.10/site-packages/_pytest/fixtures.py\", line 693, in _compute_fixture_value\n    fixturedef.execute(request=subrequest)\n  File \"/usr/local/lib/python3.10/site-packages/_pytest/fixtures.py\", line 1069, in execute\n    result = ihook.pytest_fixture_setup(fixturedef=self, request=request)\n  File \"/usr/local/lib/python3.10/site-packages/pluggy/_hooks.py\", line 513, in __call__\n    return self._hookexec(self.name, self._hookimpls.copy(), kwargs, firstresult)\n  File \"/usr/local/lib/python3.10/site-packages/pluggy/_manager.py\", line 120, in _hookexec\n    return self._inner_hookexec(hook_name, methods, kwargs, firstresult)\n  File \"/usr/local/lib/python3.10/site-packages/pluggy/_callers.py\", line 182, in _multicall\n    return outcome.get_result()\n  File \"/usr/local/lib/python3.10/site-packages/pluggy/_result.py\", line 100, in get_result\n    raise exc.with_traceback(exc.__traceback__)\n  File \"/usr/local/lib/python3.10/site-packages/pluggy/_callers.py\", line 103, in _multicall\n    res = hook_impl.function(*args)\n  File \"/usr/local/lib/python3.10/site-packages/_pytest/fixtures.py\", line 1123, in pytest_fixture_setup\n    result = call_fixture_func(fixturefunc, request, kwargs)\n  File \"/usr/local/lib/python3.10/site-packages/_pytest/fixtures.py\", line 895, in call_fixture_func\n    fixture_result = next(generator)\n  File \"/app/conftest.py\", line 96, in driver\n    pytest.fail(f\"Could not initialize WebDriver for {selenium_browser}: {str(e)}\")\n  File \"/usr/local/lib/python3.10/site-packages/_pytest/outcomes.py\", line 198, in fail\n    raise Failed(msg=reason, pytrace=pytrace)\nFailed: Could not initialize WebDriver for chrome: Message: wait: http://172.17.0.4:4444/ does not respond in 30s","flaky":false,"newFailed":false,"newBroken":false,"newPassed":false,"retriesCount":0,"retriesStatusChange":false,"beforeStages":[{"name":"base_url","time":{"start":1740704058754,"stop":1740704058755,"duration":1},"status":"passed","steps":[],"attachments":[],"parameters":[],"stepsCount":0,"attachmentsCount":0,"shouldDisplayMessage":false,"hasContent":false,"attachmentStep":false},{"name":"delete_output_dir","time":{"start":1740704058755,"stop":1740704058755,"duration":0},"status":"passed","steps":[],"attachments":[],"parameters":[],"stepsCount":0,"attachmentsCount":0,"shouldDisplayMessage":false,"hasContent":false,"attachmentStep":false},{"name":"_session_faker","time":{"start":1740704058755,"stop":1740704058782,"duration":27},"status":"passed","steps":[],"attachments":[],"parameters":[],"stepsCount":0,"attachmentsCount":0,"shouldDisplayMessage":false,"hasContent":false,"attachmentStep":false},{"name":"_verify_url","time":{"start":1740704058755,"stop":1740704058755,"duration":0},"status":"passed","steps":[],"attachments":[],"parameters":[],"stepsCount":0,"attachmentsCount":0,"shouldDisplayMessage":false,"hasContent":false,"attachmentStep":false},{"name":"pytestconfig","time":{"start":1740704058755,"stop":1740704058755,"duration":0},"status":"passed","steps":[],"attachments":[],"parameters":[],"stepsCount":0,"attachmentsCount":0,"shouldDisplayMessage":false,"hasContent":false,"attachmentStep":false},{"name":"sensitive_url","time":{"start":1740704058782,"stop":1740704058787,"duration":5},"status":"passed","steps":[],"attachments":[],"parameters":[],"stepsCount":0,"attachmentsCount":0,"shouldDisplayMessage":false,"hasContent":false,"attachmentStep":false},{"name":"_skip_sensitive","time":{"start":1740704058787,"stop":1740704058787,"duration":0},"status":"passed","steps":[],"attachments":[],"parameters":[],"stepsCount":0,"attachmentsCount":0,"shouldDisplayMessage":false,"hasContent":false,"attachmentStep":false},{"name":"remote_url","time":{"start":1740704058787,"stop":1740704058787,"duration":0},"status":"passed","steps":[],"attachments":[],"parameters":[],"stepsCount":0,"attachmentsCount":0,"shouldDisplayMessage":false,"hasContent":false,"attachmentStep":false},{"name":"driver","time":{"start":1740704058788,"stop":1740704098720,"duration":39932},"status":"failed","statusMessage":"Failed: Could not initialize WebDriver for chrome: Message: wait: http://172.17.0.4:4444/ does not respond in 30s\n\n","statusTrace":"  File \"/usr/local/lib/python3.10/site-packages/pluggy/_callers.py\", line 103, in _multicall\n    res = hook_impl.function(*args)\n  File \"/usr/local/lib/python3.10/site-packages/_pytest/fixtures.py\", line 1123, in pytest_fixture_setup\n    result = call_fixture_func(fixturefunc, request, kwargs)\n  File \"/usr/local/lib/python3.10/site-packages/_pytest/fixtures.py\", line 895, in call_fixture_func\n    fixture_result = next(generator)\n  File \"/app/conftest.py\", line 96, in driver\n    pytest.fail(f\"Could not initialize WebDriver for {selenium_browser}: {str(e)}\")\n  File \"/usr/local/lib/python3.10/site-packages/_pytest/outcomes.py\", line 198, in fail\n    raise Failed(msg=reason, pytrace=pytrace)\n","steps":[],"attachments":[{"uid":"f51c64b472067ce","name":"webdriver_exception_chrome","source":"f51c64b472067ce.txt","type":"text/plain","size":63}],"parameters":[],"stepsCount":0,"attachmentsCount":1,"shouldDisplayMessage":true,"hasContent":true,"attachmentStep":false}],"testStage":{"description":"Basic test to verify setup is working","status":"failed","statusMessage":"Failed: Could not initialize WebDriver for chrome: Message: wait: http://172.17.0.4:4444/ does not respond in 30s","statusTrace":"Traceback (most recent call last):\n  File \"/app/conftest.py\", line 73, in driver\n    driver = WebDriverFactory.create_driver(\n  File \"/app/utils/webdriver_factory.py\", line 167, in create_driver\n    driver = WebDriverFactory._create_chrome_driver(\n  File \"/app/utils/webdriver_factory.py\", line 315, in _create_chrome_driver\n    driver = webdriver.Remote(\n  File \"/usr/local/lib/python3.10/site-packages/selenium/webdriver/remote/webdriver.py\", line 208, in __init__\n    self.start_session(capabilities)\n  File \"/usr/local/lib/python3.10/site-packages/selenium/webdriver/remote/webdriver.py\", line 292, in start_session\n    response = self.execute(Command.NEW_SESSION, caps)[\"value\"]\n  File \"/usr/local/lib/python3.10/site-packages/selenium/webdriver/remote/webdriver.py\", line 347, in execute\n    self.error_handler.check_response(response)\n  File \"/usr/local/lib/python3.10/site-packages/selenium/webdriver/remote/errorhandler.py\", line 229, in check_response\n    raise exception_class(message, screen, stacktrace)\nselenium.common.exceptions.SessionNotCreatedException: Message: wait: http://172.17.0.4:4444/ does not respond in 30s\n\n\nDuring handling of the above exception, another exception occurred:\n\nTraceback (most recent call last):\n  File \"/usr/local/lib/python3.10/site-packages/_pytest/runner.py\", line 341, in from_call\n    result: Optional[TResult] = func()\n  File \"/usr/local/lib/python3.10/site-packages/_pytest/runner.py\", line 262, in <lambda>\n    lambda: ihook(item=item, **kwds), when=when, reraise=reraise\n  File \"/usr/local/lib/python3.10/site-packages/pluggy/_hooks.py\", line 513, in __call__\n    return self._hookexec(self.name, self._hookimpls.copy(), kwargs, firstresult)\n  File \"/usr/local/lib/python3.10/site-packages/pluggy/_manager.py\", line 120, in _hookexec\n    return self._inner_hookexec(hook_name, methods, kwargs, firstresult)\n  File \"/usr/local/lib/python3.10/site-packages/pluggy/_callers.py\", line 182, in _multicall\n    return outcome.get_result()\n  File \"/usr/local/lib/python3.10/site-packages/pluggy/_result.py\", line 100, in get_result\n    raise exc.with_traceback(exc.__traceback__)\n  File \"/usr/local/lib/python3.10/site-packages/pluggy/_callers.py\", line 103, in _multicall\n    res = hook_impl.function(*args)\n  File \"/usr/local/lib/python3.10/site-packages/_pytest/runner.py\", line 157, in pytest_runtest_setup\n    item.session._setupstate.setup(item)\n  File \"/usr/local/lib/python3.10/site-packages/_pytest/runner.py\", line 497, in setup\n    raise exc\n  File \"/usr/local/lib/python3.10/site-packages/_pytest/runner.py\", line 494, in setup\n    col.setup()\n  File \"/usr/local/lib/python3.10/site-packages/_pytest/python.py\", line 1795, in setup\n    self._request._fillfixtures()\n  File \"/usr/local/lib/python3.10/site-packages/_pytest/fixtures.py\", line 566, in _fillfixtures\n    item.funcargs[argname] = self.getfixturevalue(argname)\n  File \"/usr/local/lib/python3.10/site-packages/_pytest/fixtures.py\", line 585, in getfixturevalue\n    fixturedef = self._get_active_fixturedef(argname)\n  File \"/usr/local/lib/python3.10/site-packages/_pytest/fixtures.py\", line 607, in _get_active_fixturedef\n    self._compute_fixture_value(fixturedef)\n  File \"/usr/local/lib/python3.10/site-packages/_pytest/fixtures.py\", line 693, in _compute_fixture_value\n    fixturedef.execute(request=subrequest)\n  File \"/usr/local/lib/python3.10/site-packages/_pytest/fixtures.py\", line 1069, in execute\n    result = ihook.pytest_fixture_setup(fixturedef=self, request=request)\n  File \"/usr/local/lib/python3.10/site-packages/pluggy/_hooks.py\", line 513, in __call__\n    return self._hookexec(self.name, self._hookimpls.copy(), kwargs, firstresult)\n  File \"/usr/local/lib/python3.10/site-packages/pluggy/_manager.py\", line 120, in _hookexec\n    return self._inner_hookexec(hook_name, methods, kwargs, firstresult)\n  File \"/usr/local/lib/python3.10/site-packages/pluggy/_callers.py\", line 182, in _multicall\n    return outcome.get_result()\n  File \"/usr/local/lib/python3.10/site-packages/pluggy/_result.py\", line 100, in get_result\n    raise exc.with_traceback(exc.__traceback__)\n  File \"/usr/local/lib/python3.10/site-packages/pluggy/_callers.py\", line 103, in _multicall\n    res = hook_impl.function(*args)\n  File \"/usr/local/lib/python3.10/site-packages/_pytest/fixtures.py\", line 1123, in pytest_fixture_setup\n    result = call_fixture_func(fixturefunc, request, kwargs)\n  File \"/usr/local/lib/python3.10/site-packages/_pytest/fixtures.py\", line 895, in call_fixture_func\n    fixture_result = next(generator)\n  File \"/app/conftest.py\", line 96, in driver\n    pytest.fail(f\"Could not initialize WebDriver for {selenium_browser}: {str(e)}\")\n  File \"/usr/local/lib/python3.10/site-packages/_pytest/outcomes.py\", line 198, in fail\n    raise Failed(msg=reason, pytrace=pytrace)\nFailed: Could not initialize WebDriver for chrome: Message: wait: http://172.17.0.4:4444/ does not respond in 30s","steps":[],"attachments":[{"uid":"f27a1a882cb0516e","name":"log","source":"f27a1a882cb0516e.txt","type":"text/plain","size":1509},{"uid":"18d4af510ffb834e","name":"stdout","source":"18d4af510ffb834e.txt","type":"text/plain","size":1533}],"parameters":[],"stepsCount":0,"attachmentsCount":2,"shouldDisplayMessage":true,"hasContent":true,"attachmentStep":false},"afterStages":[],"labels":[{"name":"epic","value":"Setup Verification"},{"name":"story","value":"Simple Test"},{"name":"feature","value":"Basic Test"},{"name":"severity","value":"normal"},{"name":"tag","value":"nondestructive"},{"name":"parentSuite","value":"tests"},{"name":"suite","value":"basic_test"},{"name":"subSuite","value":"TestBasic"},{"name":"host","value":"33c69f3255ac"},{"name":"thread","value":"1-MainThread"},{"name":"framework","value":"pytest"},{"name":"language","value":"cpython3"},{"name":"package","value":"tests.basic_test"},{"name":"resultFormat","value":"allure2"}],"parameters":[{"name":"selenium_browser","value":"'chrome'"}],"links":[],"hidden":true,"retry":true,"extra":{"categories":[],"tags":["nondestructive"]},"source":"b61f3aef7729b469.json","parameterValues":["'chrome'"]}