INFO     utils.webdriver_factory:webdriver_factory.py:94 Using localhost:8000 for application
INFO     utils.webdriver_factory:webdriver_factory.py:156 Creating chrome latest WebDriver with remote=True, remote_url=http://selenoid:4444/wd/hub
WARNING  utils.webdriver_factory:webdriver_factory.py:121 Error connecting to Selenoid: HTTPConnectionPool(host='selenoid', port=4444): Max retries exceeded with url: /status (Caused by NameResolutionError("<urllib3.connection.HTTPConnection object at 0x7f89ac823100>: Failed to resolve 'selenoid' ([Errno -2] Name or service not known)"))
WARNING  utils.webdriver_factory:webdriver_factory.py:162 Could not verify Selenoid connection at http://selenoid:4444/wd/hub
WARNING  utils.webdriver_factory:webdriver_factory.py:163 Proceeding anyway, but this might cause issues
INFO     utils.webdriver_factory:webdriver_factory.py:314 Connecting to Selenoid at http://selenoid:4444/wd/hub with Chrome latest
WARNING  urllib3.connectionpool:connectionpool.py:868 Retrying (Retry(total=2, connect=None, read=None, redirect=None, status=None)) after connection broken by 'NameResolutionError("<urllib3.connection.HTTPConnection object at 0x7f89ac820640>: Failed to resolve 'selenoid' ([Errno -2] Name or service not known)")': /wd/hub/session
WARNING  urllib3.connectionpool:connectionpool.py:868 Retrying (Retry(total=1, connect=None, read=None, redirect=None, status=None)) after connection broken by 'NameResolutionError("<urllib3.connection.HTTPConnection object at 0x7f89ac821f00>: Failed to resolve 'selenoid' ([Errno -2] Name or service not known)")': /wd/hub/session
WARNING  urllib3.connectionpool:connectionpool.py:868 Retrying (Retry(total=0, connect=None, read=None, redirect=None, status=None)) after connection broken by 'NameResolutionError("<urllib3.connection.HTTPConnection object at 0x7f89ac8207f0>: Failed to resolve 'selenoid' ([Errno -2] Name or service not known)")': /wd/hub/session
ERROR    utils.webdriver_factory:webdriver_factory.py:321 Failed to create Remote WebDriver: HTTPConnectionPool(host='selenoid', port=4444): Max retries exceeded with url: /wd/hub/session (Caused by NameResolutionError("<urllib3.connection.HTTPConnection object at 0x7f89ac820b50>: Failed to resolve 'selenoid' ([Errno -2] Name or service not known)"))
ERROR    utils.webdriver_factory:webdriver_factory.py:329 Could not get Selenoid status: HTTPConnectionPool(host='selenoid', port=4444): Max retries exceeded with url: /status (Caused by NameResolutionError("<urllib3.connection.HTTPConnection object at 0x7f89ac823af0>: Failed to resolve 'selenoid' ([Errno -2] Name or service not known)"))
ERROR    utils.webdriver_factory:webdriver_factory.py:201 Failed to create WebDriver: HTTPConnectionPool(host='selenoid', port=4444): Max retries exceeded with url: /wd/hub/session (Caused by NameResolutionError("<urllib3.connection.HTTPConnection object at 0x7f89ac820b50>: Failed to resolve 'selenoid' ([Errno -2] Name or service not known)"))