{"uuid": "489827e2-64fd-45fd-ad9e-5cdd145f5b14", "children": ["c5045da8-c7a5-4fdd-bcc4-7d465206f555"], "befores": [{"name": "driver", "status": "broken", "statusDetails": {"message": "urllib3.exceptions.MaxRetryError: HTTPConnectionPool(host='selenoid', port=4444): Max retries exceeded with url: /wd/hub/session (Caused by NameResolutionError(\"<urllib3.connection.HTTPConnection object at 0x7f14e02fa680>: Failed to resolve 'selenoid' ([Errno -2] Name or service not known)\"))\n", "trace": "  File \"/usr/local/lib/python3.10/site-packages/pluggy/_callers.py\", line 103, in _multicall\n    res = hook_impl.function(*args)\n  File \"/usr/local/lib/python3.10/site-packages/_pytest/fixtures.py\", line 1123, in pytest_fixture_setup\n    result = call_fixture_func(fixturefunc, request, kwargs)\n  File \"/usr/local/lib/python3.10/site-packages/_pytest/fixtures.py\", line 895, in call_fixture_func\n    fixture_result = next(generator)\n  File \"/app/conftest.py\", line 73, in driver\n    driver = WebDriverFactory.create_driver(\n  File \"/app/utils/webdriver_factory.py\", line 167, in create_driver\n    driver = WebDriverFactory._create_chrome_driver(\n  File \"/app/utils/webdriver_factory.py\", line 315, in _create_chrome_driver\n    driver = webdriver.Remote(\n  File \"/usr/local/lib/python3.10/site-packages/selenium/webdriver/remote/webdriver.py\", line 208, in __init__\n    self.start_session(capabilities)\n  File \"/usr/local/lib/python3.10/site-packages/selenium/webdriver/remote/webdriver.py\", line 292, in start_session\n    response = self.execute(Command.NEW_SESSION, caps)[\"value\"]\n  File \"/usr/local/lib/python3.10/site-packages/selenium/webdriver/remote/webdriver.py\", line 345, in execute\n    response = self.command_executor.execute(driver_command, params)\n  File \"/usr/local/lib/python3.10/site-packages/selenium/webdriver/remote/remote_connection.py\", line 300, in execute\n    return self._request(command_info[0], url, body=data)\n  File \"/usr/local/lib/python3.10/site-packages/selenium/webdriver/remote/remote_connection.py\", line 321, in _request\n    response = self._conn.request(method, url, body=body, headers=headers)\n  File \"/usr/local/lib/python3.10/site-packages/urllib3/_request_methods.py\", line 143, in request\n    return self.request_encode_body(\n  File \"/usr/local/lib/python3.10/site-packages/urllib3/_request_methods.py\", line 278, in request_encode_body\n    return self.urlopen(method, url, **extra_kw)\n  File \"/usr/local/lib/python3.10/site-packages/urllib3/poolmanager.py\", line 443, in urlopen\n    response = conn.urlopen(method, u.request_uri, **kw)\n  File \"/usr/local/lib/python3.10/site-packages/urllib3/connectionpool.py\", line 871, in urlopen\n    return self.urlopen(\n  File \"/usr/local/lib/python3.10/site-packages/urllib3/connectionpool.py\", line 871, in urlopen\n    return self.urlopen(\n  File \"/usr/local/lib/python3.10/site-packages/urllib3/connectionpool.py\", line 871, in urlopen\n    return self.urlopen(\n  File \"/usr/local/lib/python3.10/site-packages/urllib3/connectionpool.py\", line 841, in urlopen\n    retries = retries.increment(\n  File \"/usr/local/lib/python3.10/site-packages/urllib3/util/retry.py\", line 519, in increment\n    raise MaxRetryError(_pool, url, reason) from reason  # type: ignore[arg-type]\n"}, "start": 1740703657626, "stop": 1740703678720}], "start": 1740703657626, "stop": 1740703678724}