{"name": "test_basic_setup[chrome]", "status": "failed", "statusDetails": {"message": "Failed: Could not initialize WebDriver for chrome: Message: unknown error: net::ERR_CONNECTION_REFUSED\n  (Session info: chrome=128.0.6613.137)\nStacktrace:\n#0 0x562b7b6a30ca <unknown>\n#1 0x562b7b36f2b0 <unknown>\n#2 0x562b7b367471 <unknown>\n#3 0x562b7b357649 <unknown>\n#4 0x562b7b3593b4 <unknown>\n#5 0x562b7b3578fd <unknown>\n#6 0x562b7b35717c <unknown>\n#7 0x562b7b35706d <unknown>\n#8 0x562b7b355078 <unknown>\n#9 0x562b7b35570a <unknown>\n#10 0x562b7b371bd1 <unknown>\n#11 0x562b7b402975 <unknown>\n#12 0x562b7b3e3902 <unknown>\n#13 0x562b7b401e26 <unknown>\n#14 0x562b7b3e36a3 <unknown>\n#15 0x562b7b3b14f3 <unknown>\n#16 0x562b7b3b24fe <unknown>\n#17 0x562b7b669d7b <unknown>\n#18 0x562b7b66dd31 <unknown>\n#19 0x562b7b655c85 <unknown>\n#20 0x562b7b66e8a2 <unknown>\n#21 0x562b7b63ae1f <unknown>\n#22 0x562b7b691e48 <unknown>\n#23 0x562b7b692013 <unknown>\n#24 0x562b7b6a1ebc <unknown>\n#25 0x7fe955c33ac3 <unknown>", "trace": "Traceback (most recent call last):\n  File \"/app/conftest.py\", line 88, in driver\n    driver.get(base_url)\n  File \"/usr/local/lib/python3.10/site-packages/selenium/webdriver/remote/webdriver.py\", line 356, in get\n    self.execute(Command.GET, {\"url\": url})\n  File \"/usr/local/lib/python3.10/site-packages/selenium/webdriver/remote/webdriver.py\", line 347, in execute\n    self.error_handler.check_response(response)\n  File \"/usr/local/lib/python3.10/site-packages/selenium/webdriver/remote/errorhandler.py\", line 229, in check_response\n    raise exception_class(message, screen, stacktrace)\nselenium.common.exceptions.WebDriverException: Message: unknown error: net::ERR_CONNECTION_REFUSED\n  (Session info: chrome=128.0.6613.137)\nStacktrace:\n#0 0x562b7b6a30ca <unknown>\n#1 0x562b7b36f2b0 <unknown>\n#2 0x562b7b367471 <unknown>\n#3 0x562b7b357649 <unknown>\n#4 0x562b7b3593b4 <unknown>\n#5 0x562b7b3578fd <unknown>\n#6 0x562b7b35717c <unknown>\n#7 0x562b7b35706d <unknown>\n#8 0x562b7b355078 <unknown>\n#9 0x562b7b35570a <unknown>\n#10 0x562b7b371bd1 <unknown>\n#11 0x562b7b402975 <unknown>\n#12 0x562b7b3e3902 <unknown>\n#13 0x562b7b401e26 <unknown>\n#14 0x562b7b3e36a3 <unknown>\n#15 0x562b7b3b14f3 <unknown>\n#16 0x562b7b3b24fe <unknown>\n#17 0x562b7b669d7b <unknown>\n#18 0x562b7b66dd31 <unknown>\n#19 0x562b7b655c85 <unknown>\n#20 0x562b7b66e8a2 <unknown>\n#21 0x562b7b63ae1f <unknown>\n#22 0x562b7b691e48 <unknown>\n#23 0x562b7b692013 <unknown>\n#24 0x562b7b6a1ebc <unknown>\n#25 0x7fe955c33ac3 <unknown>\n\n\nDuring handling of the above exception, another exception occurred:\n\nTraceback (most recent call last):\n  File \"/usr/local/lib/python3.10/site-packages/_pytest/runner.py\", line 341, in from_call\n    result: Optional[TResult] = func()\n  File \"/usr/local/lib/python3.10/site-packages/_pytest/runner.py\", line 262, in <lambda>\n    lambda: ihook(item=item, **kwds), when=when, reraise=reraise\n  File \"/usr/local/lib/python3.10/site-packages/pluggy/_hooks.py\", line 513, in __call__\n    return self._hookexec(self.name, self._hookimpls.copy(), kwargs, firstresult)\n  File \"/usr/local/lib/python3.10/site-packages/pluggy/_manager.py\", line 120, in _hookexec\n    return self._inner_hookexec(hook_name, methods, kwargs, firstresult)\n  File \"/usr/local/lib/python3.10/site-packages/pluggy/_callers.py\", line 182, in _multicall\n    return outcome.get_result()\n  File \"/usr/local/lib/python3.10/site-packages/pluggy/_result.py\", line 100, in get_result\n    raise exc.with_traceback(exc.__traceback__)\n  File \"/usr/local/lib/python3.10/site-packages/pluggy/_callers.py\", line 103, in _multicall\n    res = hook_impl.function(*args)\n  File \"/usr/local/lib/python3.10/site-packages/_pytest/runner.py\", line 157, in pytest_runtest_setup\n    item.session._setupstate.setup(item)\n  File \"/usr/local/lib/python3.10/site-packages/_pytest/runner.py\", line 497, in setup\n    raise exc\n  File \"/usr/local/lib/python3.10/site-packages/_pytest/runner.py\", line 494, in setup\n    col.setup()\n  File \"/usr/local/lib/python3.10/site-packages/_pytest/python.py\", line 1795, in setup\n    self._request._fillfixtures()\n  File \"/usr/local/lib/python3.10/site-packages/_pytest/fixtures.py\", line 566, in _fillfixtures\n    item.funcargs[argname] = self.getfixturevalue(argname)\n  File \"/usr/local/lib/python3.10/site-packages/_pytest/fixtures.py\", line 585, in getfixturevalue\n    fixturedef = self._get_active_fixturedef(argname)\n  File \"/usr/local/lib/python3.10/site-packages/_pytest/fixtures.py\", line 607, in _get_active_fixturedef\n    self._compute_fixture_value(fixturedef)\n  File \"/usr/local/lib/python3.10/site-packages/_pytest/fixtures.py\", line 693, in _compute_fixture_value\n    fixturedef.execute(request=subrequest)\n  File \"/usr/local/lib/python3.10/site-packages/_pytest/fixtures.py\", line 1069, in execute\n    result = ihook.pytest_fixture_setup(fixturedef=self, request=request)\n  File \"/usr/local/lib/python3.10/site-packages/pluggy/_hooks.py\", line 513, in __call__\n    return self._hookexec(self.name, self._hookimpls.copy(), kwargs, firstresult)\n  File \"/usr/local/lib/python3.10/site-packages/pluggy/_manager.py\", line 120, in _hookexec\n    return self._inner_hookexec(hook_name, methods, kwargs, firstresult)\n  File \"/usr/local/lib/python3.10/site-packages/pluggy/_callers.py\", line 182, in _multicall\n    return outcome.get_result()\n  File \"/usr/local/lib/python3.10/site-packages/pluggy/_result.py\", line 100, in get_result\n    raise exc.with_traceback(exc.__traceback__)\n  File \"/usr/local/lib/python3.10/site-packages/pluggy/_callers.py\", line 103, in _multicall\n    res = hook_impl.function(*args)\n  File \"/usr/local/lib/python3.10/site-packages/_pytest/fixtures.py\", line 1123, in pytest_fixture_setup\n    result = call_fixture_func(fixturefunc, request, kwargs)\n  File \"/usr/local/lib/python3.10/site-packages/_pytest/fixtures.py\", line 895, in call_fixture_func\n    fixture_result = next(generator)\n  File \"/app/conftest.py\", line 96, in driver\n    pytest.fail(f\"Could not initialize WebDriver for {selenium_browser}: {str(e)}\")\n  File \"/usr/local/lib/python3.10/site-packages/_pytest/outcomes.py\", line 198, in fail\n    raise Failed(msg=reason, pytrace=pytrace)\nFailed: Could not initialize WebDriver for chrome: Message: unknown error: net::ERR_CONNECTION_REFUSED\n  (Session info: chrome=128.0.6613.137)\nStacktrace:\n#0 0x562b7b6a30ca <unknown>\n#1 0x562b7b36f2b0 <unknown>\n#2 0x562b7b367471 <unknown>\n#3 0x562b7b357649 <unknown>\n#4 0x562b7b3593b4 <unknown>\n#5 0x562b7b3578fd <unknown>\n#6 0x562b7b35717c <unknown>\n#7 0x562b7b35706d <unknown>\n#8 0x562b7b355078 <unknown>\n#9 0x562b7b35570a <unknown>\n#10 0x562b7b371bd1 <unknown>\n#11 0x562b7b402975 <unknown>\n#12 0x562b7b3e3902 <unknown>\n#13 0x562b7b401e26 <unknown>\n#14 0x562b7b3e36a3 <unknown>\n#15 0x562b7b3b14f3 <unknown>\n#16 0x562b7b3b24fe <unknown>\n#17 0x562b7b669d7b <unknown>\n#18 0x562b7b66dd31 <unknown>\n#19 0x562b7b655c85 <unknown>\n#20 0x562b7b66e8a2 <unknown>\n#21 0x562b7b63ae1f <unknown>\n#22 0x562b7b691e48 <unknown>\n#23 0x562b7b692013 <unknown>\n#24 0x562b7b6a1ebc <unknown>\n#25 0x7fe955c33ac3 <unknown>"}, "description": "Basic test to verify setup is working", "attachments": [{"name": "log", "source": "35875950-cf30-4813-8b48-99f28a9f7ff4-attachment.txt", "type": "text/plain"}, {"name": "stdout", "source": "de60022b-adce-4ddf-9793-332618e5e43d-attachment.txt", "type": "text/plain"}], "parameters": [{"name": "selenium_browser", "value": "'chrome'"}], "start": 1740707070900, "stop": 1740707070900, "uuid": "0fe2e480-73e0-4abe-bed9-c434da11787f", "historyId": "d8e196c5bf0e40e1f6371b2b68db7725", "testCaseId": "7f30d83d04c494caeb2e9985a058fc1e", "fullName": "tests.basic_test.TestBasic#test_basic_setup", "labels": [{"name": "epic", "value": "Setup Verification"}, {"name": "severity", "value": "normal"}, {"name": "story", "value": "Simple Test"}, {"name": "feature", "value": "Basic Test"}, {"name": "tag", "value": "nondestructive"}, {"name": "parentSuite", "value": "tests"}, {"name": "suite", "value": "basic_test"}, {"name": "subSuite", "value": "TestBasic"}, {"name": "host", "value": "bc5af2ad4740"}, {"name": "thread", "value": "1-MainThread"}, {"name": "framework", "value": "pytest"}, {"name": "language", "value": "cpython3"}, {"name": "package", "value": "tests.basic_test"}]}